Workbook

Sheet LCA 
A1: LCA
A2: embodied emissions | B2: =SUM(B8:D19)*2/1000 -> 400.35587
A3: operational emissions (fossil) | B3: =SUM(C57:C59)*60/1000 -> 8364.9434 | C3: =B4/B3 -> 0.10988924 | D3: =B3/B2 -> 20.89377
A4: operational emissions (green) | B4: =SUM(D57:D59)*60/1000 -> 919.21727 | D4: =B4/B2 -> 2.2960005
A6: Building Systems GWP
B7: Heating | C7: Cooling | D7: Ventilation
A8: =Heating!A81 -> Concrete Core Actiation | B8: =Heating!C81 -> 21787.352
A9: =Heating!A82 -> Heating: Pipes | B9: =Heating!C82 -> 22534.698
A10: Heating: Pipe Insulation | B10: =SUM(Heating!C83:C84) -> 450.27472
A11: Convector | B11: =Heating!C85 -> 32294.408 | Q11: Legend:
A12: Air Chiller | C12: =SUM(Cooling!C56:C58) -> 11491.612 | Q12: grey = no touching
A13: =Cooling!A59 -> Cooling: Pipes | C13: =Cooling!C59 -> 10667.292 | Q13: yellow= editable
A14: Cooling: Pipe Insulation | C14: =Cooling!C60 -> 724.4512 | Q14: blue = comment
A15: =Cooling!A61 -> Heat Exchanger | C15: =Cooling!C61 -> 1442.0784
A16: =Cooling!A62 -> Fancoil | C16: =Cooling!C62 -> 3212.2944
A17: =Ventilation!A100 -> AL-KO | D17: =Ventilation!C100 -> 52117.75
A18: =Ventilation!A101 -> Ducts | D18: =Ventilation!C101 -> 35621.847
A19: =Ventilation!A103 -> Valve | D19: =SUM(Ventilation!C102:C103) -> 7833.8772
B20: =SUM(B8:B19) -> 77066.733 | C20: =SUM(C8:C19) -> 27537.727 | D20: =SUM(D17:D19) -> 95573.474
A22: Materials Building Systems kg | G22: Materials Building Systems kg
B23: Heating | C23: Cooling | D23: Ventilation | H23: Heating | I23: Cooling | J23: Ventilation
A24: C-Steel | B24: =Heating!D82 -> 4848.0718 | C24: =Cooling!D59+Cooling!D58 -> 3139.8934 | G24: C-Steel | H24: =Heating!C82 -> 22534.698 | I24: =Cooling!C59+Cooling!C58 -> 16047.995
A25: Steel | B25: =Heating!D88 -> 1638.906 | C25: =Cooling!D56+Cooling!D61+Cooling!D62 -> 7621 | D25: =Ventilation!D100+Ventilation!D101+Ventilation!D102 -> 43828.171 | G25: Steel | H25: =Heating!C88 -> 8335.7791 | I25: =Cooling!C56+Cooling!C61+Cooling!C62 -> 6451.8113 | J25: =Ventilation!C100+Ventilation!C101+Ventilation!C102 -> 94616.255
A26: Aluminium | B26: =Heating!D87 -> 85.293 | G26: Aluminium | H26: =Heating!C87 -> 1666.7958
A27: Copper/Aluminium | B27: =Heating!D90 -> 2697.52 | G27: Copper/Aluminium | H27: =Heating!C90 -> 22241.592
A28: Rockwool | B28: =Heating!D83 -> 219.52274 | G28: Rockwool | H28: =Heating!C83 -> 237.96265
A29: PE foam | B29: =Heating!D84 -> 54.397147 | G29: PE foam | H29: =Heating!C84 -> 212.31207
A30: Armaflex | C30: =Cooling!D60 -> 259.38102 | G30: Armaflex | I30: =Cooling!C60 -> 724.4512
A31: Polyethylene | B31: =Heating!D81 -> 6790.4 | G31: Polyethylene | H31: =Heating!C81 -> 21787.352
A32: Polyamid | B32: =Heating!D89 -> 5.88924 | D32: =Ventilation!D103 -> 112.2034 | G32: Polyamid | H32: =Heating!C89 -> 50.241695 | J32: =Ventilation!C103 -> 957.21843
A33: Refrigerant | C33: =Cooling!D57 -> 245 | G33: Refrigerant | I33: =Cooling!C57 -> 4313.47
A37: Total | B37: =SUM(B24:B33) -> 16340 | C37: =SUM(C24:C33) -> 11265.274 | D37: =SUM(D24:D33) -> 43940.374 | G37: Total | H37: =SUM(H24:H33) -> 77066.733 | I37: =SUM(I24:I33) -> 27537.727 | J37: =SUM(J24:J33) -> 95573.474
A48: Operational Energy in kWh
B49: District Heating | C49: Electricity
A50: Heating | B50: ='operational Energy'!U3 -> 687360.95
A51: Cooling | C51: ='operational Energy'!U4 -> 565204.04
A52: Ventilation | C52: ='operational Energy'!U5 -> 883817.98
A55: GWP of Operational Energy in kgCO2eq
B56: District Heating | C56: electricity (fossil) | D56: electricity (green)
A57: Heating (District Heating) | B57: ='operational Energy'!V3 -> 6667.4012
...

Sheet Heating
A1: System | B1: Heating | F1: pi | G1: 3.1415927 | T1: Tabs Floor
A2: Energy | B2: District Heating | T2: https://www.rehau.com/downloads/712394/rautitan.pdf
A3: Heated area | B3: 8488
A7: Composition of the System
B8: Element | C8: Material | D8: Length [m/m2] | E8: Total Length | F8: Section [m2] | G8: Volume [m3] | I8: Pipe Distance | J8: Diameter [m] | K8: Thickness | L8: kg/m | M8: kg/m3 | N8: kg
A9: Concrete Core | B9: Pipe Floor | C9: Polyethylene | D9: =(1/I9*1) -> 6.6666667 | E9: =D9*$B$3 -> 56586.667 | F9: =((J9/2)^2*$G$1)-(((J9-K9)/2)^2*G1) -> 5.969026e-05 | G9: =E9*F9 -> 3.3776729 | I9: 0.15 | J9: 0.02 | K9: 0.002 | L9: 0.12 | N9: =L9*E9 -> 6790.4
A10: Heating: Pipes | B10: DN125 | C10: C-Steel | E10: =Worksheet_Pipes!V3 -> 34.42 | F10: =((J10/2)^2*$G$1)-(((J10-K10)/2)^2*$G$1) -> 0.00069064773 | G10: =F10*E10 -> 0.023772095 | J10: 0.139 | K10: 0.0032 | L10: 10.72 | N10: =L10*E10 -> 368.9824
B11: DN100 | C11: C-Steel | E11: =Worksheet_Pipes!V4 -> 171.63 | F11: =((J11/2)^2*$G$1)-(((J11-K11)/2)^2*$G$1) -> 0.00033615041 | G11: =F11*E11 -> 0.057693496 | J11: 0.108 | K11: 0.002 | L11: 5.23 | N11: =L11*E11 -> 897.6249
B12: DN80 | C12: C-Steel | E12: =Worksheet_Pipes!V5 -> 29.97 | F12: =((J12/2)^2*$G$1)-(((J12-K12)/2)^2*$G$1) -> 0.00027614599 | G12: =F12*E12 -> 0.0082760954 | J12: 0.0889 | K12: 0.002 | L12: 4.29 | N12: =L12*E12 -> 128.5713
B13: DN65 | C13: C-Steel | E13: =Worksheet_Pipes!V6 -> 362.27 | F13: =((J13/2)^2*$G$1)-(((J13-K13)/2)^2*$G$1) -> 0.00023593361 | G13: =F13*E13 -> 0.085471668 | J13: 0.0761 | K13: 0.002 | L13: 3.65 | N13: =L13*E13 -> 1322.2855
B14: DN50 | C14: C-Steel | E14: =Worksheet_Pipes!V7 -> 253.77 | F14: =((J14/2)^2*$G$1)-(((J14-K14)/2)^2*$G$1) -> 0.00012546736 | G14: =F14*E14 -> 0.031839851 | J14: 0.054 | K14: 0.0015 | L14: 1.94 | N14: =L14*E14 -> 492.3138
B15: DN40 | C15: C-Steel | E15: =Worksheet_Pipes!V8 -> 258.84 | F15: =((J15/2)^2*$G$1)-(((J15-K15)/2)^2*$G$1) -> 9.7193023e-05 | G15: =F15*E15 -> 0.025157442 | J15: 0.042 | K15: 0.0015 | L15: 1.5 | N15: =L15*E15 -> 388.26
B16: DN32 | C16: C-Steel | E16: =Worksheet_Pipes!V9 -> 160.33 | F16: =((J16/2)^2*$G$1)-(((J16-K16)/2)^2*$G$1) -> 8.0699661e-05 | G16: =F16*E16 -> 0.012938577 | J16: 0.035 | K16: 0.0015 | L16: 1.24 | N16: =L16*E16 -> 198.8092
B17: DN25 | C17: C-Steel | E17: =Worksheet_Pipes!V10 -> 196.7 | F17: =((J17/2)^2*$G$1)-(((J17-K17)/2)^2*$G$1) -> 6.42063e-05 | G17: =F17*E17 -> 0.012629379 | J17: 0.028 | K17: 0.0015 | L17: 0.98 | N17: =L17*E17 -> 192.766
B18: DN20 | C18: C-Steel | E18: =Worksheet_Pipes!V11 -> 173.74 | F18: =((J18/2)^2*$G$1)-(((J18-K18)/2)^2*$G$1) -> 5.0069133e-05 | G18: =F18*E18 -> 0.0086990112 | J18: 0.022 | K18: 0.0015 | L18: 0.76 | N18: =L18*E18 -> 132.0424
B19: DN15 | C19: C-Steel | E19: =Worksheet_Pipes!V12 -> 166.715 | F19: =((J19/2)^2*$G$1)-(((J19-K19)/2)^2*$G$1) -> 3.2798227e-05 | G19: =F19*E19 -> 0.0054679565 | J19: 0.018 | K19: 0.0012 | L19: 0.5 | N19: =L19*E19 -> 83.3575
B20: DN12 | C20: C-Steel | E20: =Worksheet_Pipes!V13 -> 497.672 | F20: =((J20/2)^2*$G$1)-(((J20-K20)/2)^2*$G$1) -> 2.7143361e-05 | G20: =F20*E20 -> 0.013508491 | J20: 0.015 | K20: 0.0012 | L20: 0.41 | N20: =L20*E20 -> 204.04552
A21: Heating: Pipe Insulation (shaft) | B21: DN125 | C21: Rockwool | E21: =Worksheet_Pipes!AZ197+Worksheet_Pipes!BJ142 -> 0 | F21: =((J21/2)^2*$G$1)-(((J21-K21)/2)^2*$G$1) -> 0.007257079 | G21: =F21*E21 -> 0 | J21: =K21+J10 -> 0.169 | K21: 0.03 | M21: 120 | N21: =G21*M21 -> 0
B22: DN100 | C22: Rockwool | E22: =Worksheet_Pipes!AZ198+Worksheet_Pipes!BJ143 -> 0 | F22: =((J22/2)^2*$G$1)-(((J22-K22)/2)^2*$G$1) -> 0.0057962384 | G22: =F22*E22 -> 0 | J22: =K22+J11 -> 0.138 | K22: 0.03 | M22: 120 | N22: =G22*M22 -> 0
B23: DN80 | C23: Rockwool | E23: =Worksheet_Pipes!AZ199+Worksheet_Pipes!BJ144 -> 16.88 | F23: =((J23/2)^2*$G$1)-(((J23-K23)/2)^2*$G$1) -> 0.0048961722 | G23: =F23*E23 -> 0.082647386 | J23: =K23+J12 -> 0.1189 | K23: 0.03 | M23: 120 | N23: =G23*M23 -> 9.9176863
B24: DN65 | C24: Rockwool | E24: =Worksheet_Pipes!AZ200+Worksheet_Pipes!BJ145 -> 140.5 | F24: =((J24/2)^2*$G$1)-(((J24-K24)/2)^2*$G$1) -> 0.0042929864 | G24: =F24*E24 -> 0.60316458 | J24: =K24+J13 -> 0.1061 | K24: 0.03 | M24: 120 | N24: =G24*M24 -> 72.37975
B25: DN50 | C25: Rockwool | E25: =Worksheet_Pipes!AZ201+Worksheet_Pipes!BJ146 -> 225.82 | F25: =((J25/2)^2*$G$1)-(((J25-K25)/2)^2*$G$1) -> 0.0026114489 | G25: =F25*E25 -> 0.58971739 | J25: =K25+J14 -> 0.079 | K25: 0.025 | M25: 120 | N25: =G25*M25 -> 70.766087
B26: DN40 | C26: Rockwool | E26: =Worksheet_Pipes!AZ202+Worksheet_Pipes!BJ147 -> 91.56 | F26: =((J26/2)^2*$G$1)-(((J26-K26)/2)^2*$G$1) -> 0.00214021 | G26: =F26*E26 -> 0.19595763 | J26: =K26+J15 -> 0.067 | K26: 0.025 | M26: 120 | N26: =G26*M26 -> 23.514915
B27: DN32 | C27: Rockwool | E27: =Worksheet_Pipes!AZ203+Worksheet_Pipes!BJ148 -> 97.02 | F27: =((J27/2)^2*$G$1)-(((J27-K27)/2)^2*$G$1) -> 0.0014137167 | G27: =F27*E27 -> 0.13715879 | J27: =K27+J16 -> 0.055 | K27: 0.02 | M27: 120 | N27: =G27*M27 -> 16.459055
B28: DN25 | C28: Rockwool | E28: =Worksheet_Pipes!AZ204+Worksheet_Pipes!BJ149 -> 91.935 | F28: =((J28/2)^2*$G$1)-(((J28-K28)/2)^2*$G$1) -> 0.0011938052 | G28: =F28*E28 -> 0.10975248 | J28: =K28+J17 -> 0.048 | K28: 0.02 | M28: 120 | N28: =G28*M28 -> 13.170298
B29: DN20 | C29: Rockwool | E29: =Worksheet_Pipes!AZ205+Worksheet_Pipes!BJ150 -> 87.92 | F29: =((J29/2)^2*$G$1)-(((J29-K29)/2)^2*$G$1) -> 0.0010053096 | G29: =F29*E29 -> 0.088386824 | J29: =K29+J18 -> 0.042 | K29: 0.02 | M29: 120 | N29: =G29*M29 -> 10.606419
B30: DN15 | C30: Rockwool | E30: =Worksheet_Pipes!AZ206+Worksheet_Pipes!BJ151 -> 11.695 | F30: =((J30/2)^2*$G$1)-(((J30-K30)/2)^2*$G$1) -> 0.00087964594 | G30: =F30*E30 -> 0.010287459 | J30: =K30+J19 -> 0.038 | K30: 0.02 | M30: 120 | N30: =G30*M30 -> 1.2344951
B31: DN12 | C31: Rockwool | E31: =Worksheet_Pipes!AZ207+Worksheet_Pipes!BJ152 -> 15.64 | F31: =((J31/2)^2*$G$1)-(((J31-K31)/2)^2*$G$1) -> 0.00078539816 | G31: =F31*E31 -> 0.012283627 | J31: =K31+J20 -> 0.035 | K31: 0.02 | M31: 120 | N31: =G31*M31 -> 1.4740353
A32: Heating: Pipe Insulation (floors) | B32: DN125 | C32: PE foam | E32: =Worksheet_Pipes!H27+Worksheet_Pipes!H60 -> 34.42 | F32: =((J32/2)^2*$G$1)-(((J32-K32)/2)^2*$G$1) -> 0.0044320018 | G32: =F32*E32 -> 0.1525495 | J32: =J10+K32 -> 0.158 | K32: 0.019 | M32: 29 | N32: =G32*M32 -> 4.4239356
B33: DN100 | C33: PE foam | E33: =Worksheet_Pipes!H28+Worksheet_Pipes!H61 -> 171.63 | F33: =((J33/2)^2*$G$1)-(((J33-K33)/2)^2*$G$1) -> 0.0035068028 | G33: =F33*E33 -> 0.60187256 | J33: =J11+K33 -> 0.127 | K33: 0.019 | M33: 29 | N33: =G33*M33 -> 17.454304
B34: DN80 | C34: PE foam | E34: =Worksheet_Pipes!H29+Worksheet_Pipes!H62 -> 13.09 | F34: =((J34/2)^2*$G$1)-(((J34-K34)/2)^2*$G$1) -> 0.0029367608 | G34: =F34*E34 -> 0.038442199 | J34: =J12+K34 -> 0.1079 | K34: 0.019 | M34: 29 | N34: =G34*M34 -> 1.1148238
B35: DN65 | C35: PE foam | E35: =Worksheet_Pipes!H30+Worksheet_Pipes!H63 -> 221.77 | F35: =((J35/2)^2*$G$1)-(((J35-K35)/2)^2*$G$1) -> 0.0025547431 | G35: =F35*E35 -> 0.56656539 | J35: =J13+K35 -> 0.0951 | K35: 0.019 | M35: 29 | N35: =G35*M35 -> 16.430396
B36: DN50 | C36: PE foam | E36: =Worksheet_Pipes!H31+Worksheet_Pipes!H64 -> 27.95 | F36: =((J36/2)^2*$G$1)-(((J36-K36)/2)^2*$G$1) -> 0.0012354313 | G36: =F36*E36 -> 0.034530305 | J36: =J14+K36 -> 0.067 | K36: 0.013 | M36: 29 | N36: =G36*M36 -> 1.0013788
B37: DN40 | C37: PE foam | E37: =Worksheet_Pipes!H32+Worksheet_Pipes!H65 -> 167.28 | F37: =((J37/2)^2*$G$1)-(((J37-K37)/2)^2*$G$1) -> 0.00099038708 | G37: =F37*E37 -> 0.16567195 | J37: =J15+K37 -> 0.055 | K37: 0.013 | M37: 29 | N37: =G37*M37 -> 4.8044866
B38: DN32 | C38: PE foam | E38: =Worksheet_Pipes!H33+Worksheet_Pipes!H66 -> 63.31 | F38: =((J38/2)^2*$G$1)-(((J38-K38)/2)^2*$G$1) -> 0.00084744462 | G38: =F38*E38 -> 0.053651719 | J38: =J16+K38 -> 0.048 | K38: 0.013 | M38: 29 | N38: =G38*M38 -> 1.5558998
B39: DN25 | C39: PE foam | E39: =Worksheet_Pipes!H34+Worksheet_Pipes!H67 -> 104.765 | F39: =((J39/2)^2*$G$1)-(((J39-K39)/2)^2*$G$1) -> 0.00045945793 | G39: =F39*E39 -> 0.04813511 | J39: =J17+K39 -> 0.037 | K39: 0.009 | M39: 29 | N39: =G39*M39 -> 1.3959182
B40: DN20 | C40: PE foam | E40: =Worksheet_Pipes!H35+Worksheet_Pipes!H68 -> 85.82 | F40: =((J40/2)^2*$G$1)-(((J40-K40)/2)^2*$G$1) -> 0.00037463492 | G40: =F40*E40 -> 0.032151169 | J40: =J18+K40 -> 0.031 | K40: 0.009 | M40: 29 | N40: =G40*M40 -> 0.93238391
B41: DN15 | C41: PE foam | E41: =Worksheet_Pipes!H36+Worksheet_Pipes!H69 -> 155.02 | F41: =((J41/2)^2*$G$1)-(((J41-K41)/2)^2*$G$1) -> 0.00031808626 | G41: =F41*E41 -> 0.049309731 | J41: =J19+K41 -> 0.027 | K41: 0.009 | M41: 29 | N41: =G41*M41 -> 1.4299822
B42: DN12 | C42: PE foam | E42: =Worksheet_Pipes!H37+Worksheet_Pipes!H70 -> 482.032 | F42: =((J42/2)^2*$G$1)-(((J42-K42)/2)^2*$G$1) -> 0.00027567476 | G42: =F42*E42 -> 0.13288405 | J42: =J20+K42 -> 0.024 | K42: 0.009 | M42: 29 | N42: =G42*M42 -> 3.8536376
A43: Cooling: Pipes | B43: DN125 | C43: C-Steel | E43: =Worksheet_Pipes!Y3 -> 29.99 | F43: =((J43/2)^2*$G$1)-(((J43-K43)/2)^2*$G$1) -> 0.00069064773 | G43: =F43*E43 -> 0.020712525 | J43: 0.139 | K43: 0.0032 | L43: 10.72 | N43: =L43*E43 -> 321.4928
...

Sheet Cooling
A1: System | B1: Quantum Air Chiller | F1: pi | G1: 3.1415927 | M1: Engie - Maßstab moderner Kälteerzeugung
A2: Energy | B2: Electricity | M2: Die neue Generation luftgekühlter QUANTUM-Kältemaschinen
A3: Cooled area | B3: 297.1 | N3: width | O3: length | P3: thickness
M4: Frame | N4: 0.077 | P4: 0.01
A7: Composition of the System
B8: Element | C8: Material | D8: Quantity | E8: Amount | F8: Unit | G8: Width [m] | H8: Length | I8: Height [m] | J8: Volume [m3] | L8: Diameter [m] | M8: Thickness | N8: kg/m | O8: kg/m3 | P8: kg
A9: Air Chiller | B9: Ventilator | C9: Steel | D9: 10 | E9: 10 | F9: no | L9: 0.92
B10: Frame (upper) | C10: Steel | D10: 1 | G10: 2.279 | H10: 7.921 | I10: 0.08
B11: Frame (lower) | C11: Steel | D11: 1 | G11: 2.279 | H11: 7.921
B12: Control Panel | D12: 1
B13: Electrical Cabinet | C13: Aluminium | D13: 1 | G13: 0.3 | H13: 2.04 | I13: 1.07
B14: Compressor | G14: 0.52 | I14: 1
B15: Economizer | C15: Steel | D15: 1
B16: Shell and Tube evaporator | C16: Steel | D16: 1 | H16: 3.5 | L16: 0.5
B17: Condenser-Modules (air cooled) | C17: Steel | D17: 7 | G17: 2.23 | H17: 1.05 | I17: 1.16 | L17: Triangle
B18: Condenserlegs | C18: Steel | D18: 14
B19: Refrigerant | C19: R-1234ze | E19: 245 | F19: kg | P19: 245
B20: Betriebsgwicht (Total) | P20: 5465
A21: Pipes vertical | B21: DN 150 | C21: Steel | E21: 48.8 | F21: m | J21: =#REF!*E21 -> #REF! | L21: 0.168 | M21: 0.0032 | N21: 13.01 | P21: =N21*E21 -> 634.888
A22: Pipes horizontal | B22: DN 150 | C22: Steel | E22: 32.12 | F22: m | L22: 0.168 | M22: 0.0032 | N22: 13.01 | P22: =N22*E22 -> 417.8812
A23: Heat Exchanger | B23: Plate | C23: Stainless Steel | E23: 90 | F23: no
B24: Frame | C24: Steel (P355GH)
B25: Seal | C25: Nitrile Butadiene Rubber
B26: Total | P26: 668
A27: Fancoil | B27: 60x60 | D27: 26 | E27: 24 | F27: kg | P27: =E27*D27 -> 624
B28: 84x84 | D28: 18 | E28: 48 | F28: kg | P28: =D28*E28 -> 864
B29: Element | C29: Material | D29: Length [m/m2] | E29: Total Length | F29: Section [m2] | G29: Volume [m3] | I29: Special | J29: Diameter [m] | K29: Thickness | L29: kg/m | M29: kg/m3 | N29: kg
A30: Cooling: Pipes | B30: DN125 | C30: C-Steel | E30: =Worksheet_Pipes!Y3 -> 29.99 | F30: =((J30/2)^2*$G$1)-(((J30-K30)/2)^2*$G$1) -> 0.00069064773 | G30: =F30*E30 -> 0.020712525 | J30: 0.139 | K30: 0.0032 | L30: 10.72 | N30: =L30*E30 -> 321.4928
B31: DN100 | C31: C-Steel | E31: =Worksheet_Pipes!Y4 -> 16.94 | F31: =((J31/2)^2*$G$1)-(((J31-K31)/2)^2*$G$1) -> 0.00033615041 | G31: =F31*E31 -> 0.005694388 | J31: 0.108 | K31: 0.002 | L31: 5.23 | N31: =L31*E31 -> 88.5962
B32: DN80 | C32: C-Steel | E32: =Worksheet_Pipes!Y5 -> 39.06 | F32: =((J32/2)^2*$G$1)-(((J32-K32)/2)^2*$G$1) -> 0.00027614599 | G32: =F32*E32 -> 0.010786263 | J32: 0.0889 | K32: 0.002 | L32: 4.29 | N32: =L32*E32 -> 167.5674
B33: DN65 | C33: C-Steel | E33: =Worksheet_Pipes!Y6 -> 285.89 | F33: =((J33/2)^2*$G$1)-(((J33-K33)/2)^2*$G$1) -> 0.00023593361 | G33: =F33*E33 -> 0.067451059 | J33: 0.0761 | K33: 0.002 | L33: 3.65 | N33: =L33*E33 -> 1043.4985
B34: DN50 | C34: C-Steel | E34: =Worksheet_Pipes!Y7 -> 77.96 | F34: =((J34/2)^2*$G$1)-(((J34-K34)/2)^2*$G$1) -> 0.00012546736 | G34: =F34*E34 -> 0.0097814351 | J34: 0.054 | K34: 0.0015 | L34: 1.94 | N34: =L34*E34 -> 151.2424
B35: DN40 | C35: C-Steel | E35: =Worksheet_Pipes!Y8 -> 160.534 | F35: =((J35/2)^2*$G$1)-(((J35-K35)/2)^2*$G$1) -> 9.7193023e-05 | G35: =F35*E35 -> 0.015602785 | J35: 0.042 | K35: 0.0015 | L35: 1.5 | N35: =L35*E35 -> 240.801
B36: DN32 | C36: C-Steel | E36: =Worksheet_Pipes!Y9 -> 21.223 | F36: =((J36/2)^2*$G$1)-(((J36-K36)/2)^2*$G$1) -> 8.0699661e-05 | G36: =F36*E36 -> 0.0017126889 | J36: 0.035 | K36: 0.0015 | L36: 1.24 | N36: =L36*E36 -> 26.31652
B37: DN25 | C37: C-Steel | E37: =Worksheet_Pipes!Y10 -> 42.563 | F37: =((J37/2)^2*$G$1)-(((J37-K37)/2)^2*$G$1) -> 6.42063e-05 | G37: =F37*E37 -> 0.0027328127 | J37: 0.028 | K37: 0.0015 | L37: 0.98 | N37: =L37*E37 -> 41.71174
B38: DN20 | C38: C-Steel | E38: =Worksheet_Pipes!Y11 -> 7.76 | F38: =((J38/2)^2*$G$1)-(((J38-K38)/2)^2*$G$1) -> 5.0069133e-05 | G38: =F38*E38 -> 0.00038853647 | J38: 0.022 | K38: 0.0015 | L38: 0.76 | N38: =L38*E38 -> 5.8976
B39: DN15 | C39: C-Steel | E39: =Worksheet_Pipes!Y12 -> 0 | F39: =((J39/2)^2*$G$1)-(((J39-K39)/2)^2*$G$1) -> 3.2798227e-05 | G39: =F39*E39 -> 0 | J39: 0.018 | K39: 0.0012 | L39: 0.5 | N39: =L39*E39 -> 0
B40: DN12 | C40: C-Steel | E40: =Worksheet_Pipes!Y13 -> 0 | F40: =((J40/2)^2*$G$1)-(((J40-K40)/2)^2*$G$1) -> 2.7143361e-05 | G40: =F40*E40 -> 0 | J40: 0.015 | K40: 0.0012 | L40: 0.41 | N40: =L40*E40 -> 0
A41: Cooling: Pipe Insulation (shaft+floor) | B41: DN125 | C41: Armaflex / Kautschuck | E41: =Worksheet_Pipes!Y3 -> 29.99 | F41: =((J41/2)^2*$G$1)-(((J41-K41)/2)^2*$G$1) -> 0.0099902646 | G41: =F41*E41 -> 0.29960804 | J41: =J30+K41 -> 0.179 | K41: 0.04 | M41: 80 | N41: =G41*M41 -> 23.968643
B42: DN100 | C42: Armaflex / Kautschuck | E42: =Worksheet_Pipes!Y4 -> 16.94 | F42: =((J42/2)^2*$G$1)-(((J42-K42)/2)^2*$G$1) -> 0.0080424772 | G42: =F42*E42 -> 0.13623956 | J42: =J31+K42 -> 0.148 | K42: 0.04 | M42: 80 | N42: =G42*M42 -> 10.899165
...

Sheet Ventilation
A1: System | B1: AL-KO AT4 | H1: pi | I1: 3.1415927 | M1: https://alko-airtechnology.com/en/product/al-ko-the-at4-series-your-individual-ventilation-devices/
A2: Energy | B2: Electricity
A3: Room | B3: Openplan Office
A4: Roomarea | B4: 297.1
A7: Composition of the System
B8: Element | C8: Material | D8: Width | E8: Height | F8: Length | G8: Quantity | H8: Thickness | I8: Volume total [m3] | J8: kg/m3 | K8: kg
A9: AL-KO | B9: BF5 - 1a - Büro - LV | C9: Steel | E9: 2.83 | F9: 9.793 | K9: 805
K10: 780
K11: 691
K12: 721
K13: 780
K14: 753
K15: 707
B16: BF5 - 1b Büro | K16: 944
K17: 998
K18: 1193
K19: 687
K20: 849
K21: 802
K22: 998
K23: 1014
B24: BF5 - 1.1 Nebenräume | K24: 395
K25: 330
K26: 313
K27: 417
K28: 330
K29: 512
B30: BF5 - 2.0 Büro Ost - 1 | K30: 1160
K31: 998
K32: 944
K33: 1014
K34: 998
K35: 770
K36: 808
K37: 687
B38: BF5 -2.1 WC Ost-1 | K38: 205
K39: 275
K40: 290
K41: 394
K42: 275
...

Sheet Worksheet_Pipes
A1: UG - Horizontal (to the shaft) | R1: Total of all pipes together | U1: Total of all HEATING pipes together | X1: Total of all COOLING pipes together
A2: Part | B2: Pipe | C2: Width | D2: Length | R2: Pipe | S2: Total | U2: Pipe | V2: Total | X2: Pipe | Y2: Total
A3: connection to distributor | B3: DN65 | D3: 1.59 | R3: DN125 | S3: =SUM(H7+H60+H126+R126+AB126+AL126+AV126+BF126+H181+R181+AB181+AL181+AV181) -> 64.41 | U3: DN125 | V3: =SUM(H27+H60+BJ142+AZ197) -> 34.42 | X3: DN125 | Y3: =H42+BJ158+AZ213 -> 29.99
R4: DN100 | S4: =SUM(H8+H61+H127+R127+AB127+AL127+AV127+BF127+H182+R182+AB182+AL182+AV182) -> 188.57 | U4: DN100 | V4: =SUM(H28+H61+BJ143+AZ198) -> 171.63 | X4: DN100 | Y4: =H43+BJ159+AZ214 -> 16.94
A5: UG - Horizontal (to the shaft) | G5: Alle | R5: DN80 | S5: =SUM(H9+H62+H128+R128+AB128+AL128+AV128+BF128+H183+R183+AB183+AL183+AV183) -> 69.03 | U5: DN80 | V5: =SUM(H29+H62+BJ144+AZ199) -> 29.97 | X5: DN80 | Y5: =H44+BJ160+AZ215 -> 39.06
A6: Part | B6: Pipe | C6: Width | D6: Length | G6: Pipe | H6: Total | R6: DN65 | S6: =SUM(H10+H63+H129+R129+AB129+AL129+AV129+BF129+H184+R184+AB184+AL184+AV184) -> 649.75 | U6: DN65 | V6: =SUM(H30+H63+BJ145+AZ200) -> 362.27 | X6: DN65 | Y6: =H45+BJ161+AZ216 -> 285.89
A7: Heizungsvorlauf | B7: DN100 | D7: 59.75 | G7: DN125 | H7: =SUMIF($B$3:$B$54,G7,$D$3:$D$54) -> 64.41 | R7: DN50 | S7: =SUM(H11+H64+H130+R130+AB130+AL130+AV130+BF130+H185+R185+AB185+AL185+AV185) -> 331.73 | U7: DN50 | V7: =SUM(H31+H64+BJ146+AZ201) -> 253.77 | X7: DN50 | Y7: =H46+BJ162+AZ217 -> 77.96
B8: DN65 | D8: 15.65 | G8: DN100 | H8: =SUMIF($B$3:$B$54,G8,$D$3:$D$54) -> 188.57 | R8: DN40 | S8: =SUM(H12+H65+H131+R131+AB131+AL131+AV131+BF131+H186+R186+AB186+AL186+AV186) -> 419.374 | U8: DN40 | V8: =SUM(H32+H65+BJ147+AZ202) -> 258.84 | X8: DN40 | Y8: =H47+BJ163+AZ218 -> 160.534
B9: DN65 | D9: 10.29 | G9: DN80 | H9: =SUMIF($B$3:$B$54,G9,$D$3:$D$54) -> 13.09 | R9: DN32 | S9: =SUM(H13+H66+H132+R132+AB132+AL132+AV132+BF132+H187+R187+AB187+AL187+AV187) -> 181.553 | U9: DN32 | V9: =SUM(H33+H66+BJ148+AZ203) -> 160.33 | X9: DN32 | Y9: =H48+BJ164+AZ219 -> 21.223
B10: DN40 | D10: 40.9 | G10: DN65 | H10: =SUMIF($B$3:$B$54,G10,$D$3:$D$54) -> 406.52 | R10: DN25 | S10: =SUM(H14+H67+H133+R133+AB133+AL133+AV133+BF133+H188+R188+AB188+AL188+AV188) -> 239.263 | U10: DN25 | V10: =SUM(H34+H67+BJ149+AZ204) -> 196.7 | X10: DN25 | Y10: =H49+BJ165+AZ220 -> 42.563
B11: DN40 | D11: 40.7 | G11: DN50 | H11: =SUMIF($B$3:$B$54,G11,$D$3:$D$54) -> 43.27 | R11: DN20 | S11: =SUM(H15+H68+H134+R134+AB134+AL134+AV134+BF134+H189+R189+AB189+AL189+AV189) -> 181.5 | U11: DN20 | V11: =SUM(H35+H68+BJ150+AZ205) -> 173.74 | X11: DN20 | Y11: =H50+BJ166+AZ221 -> 7.76
B12: DN32 | D12: 2.16 | G12: DN40 | H12: =SUMIF($B$3:$B$54,G12,$D$3:$D$54) -> 167.28 | R12: DN15 | S12: =SUM(H16+H69+H135+R135+AB135+AL135+AV135+BF135+H190+R190+AB190+AL190+AV190) -> 166.715 | U12: DN15 | V12: =SUM(H36+H69+BJ151+AZ206) -> 166.715 | X12: DN15 | Y12: =H51+BJ167+AZ222 -> 0
B13: DN32 | D13: 30.02 | G13: DN32 | H13: =SUMIF($B$3:$B$54,G13,$D$3:$D$54) -> 63.31 | R13: DN12 | S13: =SUM(H17+H70+H136+R136+AB136+AL136+AV136+BF136+H191+R191+AB191+AL191+AV191) -> 497.672 | U13: DN12 | V13: =SUM(H37+H70+BJ152+AZ207) -> 497.672 | X13: DN12 | Y13: =H52+BJ168+AZ223 -> 0
B14: DN25 | D14: 12.98 | G14: DN25 | H14: =SUMIF($B$3:$B$54,G14,$D$3:$D$54) -> 26.905
B15: DN12 | D15: 50.71 | G15: DN20 | H15: =SUMIF($B$3:$B$54,G15,$D$3:$D$54) -> 0
G16: DN15 | H16: =SUMIF($B$3:$B$54,G16,$D$3:$D$54) -> 0
A17: Heizungsrücklauf | B17: DN100 | D17: 58.13 | G17: DN12 | H17: =SUMIF($B$3:$B$54,G17,$D$3:$D$54) -> 98.91
B18: DN65 | D18: 15.74 | G18: DN10 | H18: =SUMIF($B$3:$B$54,G18,$D$3:$D$54) -> 0
B19: DN65 | D19: 9.73
B20: DN40 | D20: 29.58
B21: DN40 | D21: 15.7
B22: DN40 | D22: 40.4
B23: DN32 | D23: 31.13
B24: DN25 | D24: 13.925
B25: DN12 | D25: 48.2 | G25: Heat
G26: Pipe | H26: Total
A27: Betonkern Vorlauf | B27: DN125 | D27: 17.6 | G27: DN125 | H27: =SUMIF($B$7:$B$42,G27,$D$7:$D$42) -> 34.42
B28: DN100 | D28: 26.7 | G28: DN100 | H28: =SUMIF($B$7:$B$42,G28,$D$7:$D$42) -> 171.63
B29: DN80 | D29: 8.4 | G29: DN80 | H29: =SUMIF($B$7:$B$42,G29,$D$7:$D$42) -> 13.09
B30: DN65 | D30: 16.59 | G30: DN65 | H30: =SUMIF($B$7:$B$42,G30,$D$7:$D$42) -> 221.77
B31: DN65 | D31: 36.71 | G31: DN50 | H31: =SUMIF($B$7:$B$42,G31,$D$7:$D$42) -> 27.95
B32: DN65 | D32: 28 | G32: DN40 | H32: =SUMIF($B$7:$B$42,G32,$D$7:$D$42) -> 167.28
B33: DN50 | D33: 14 | G33: DN32 | H33: =SUMIF($B$7:$B$42,G33,$D$7:$D$42) -> 63.31
G34: DN25 | H34: =SUMIF($B$7:$B$42,G34,$D$7:$D$42) -> 26.905
A35: BTK Rücklauf | B35: DN125 | D35: 16.82 | G35: DN20 | H35: =SUMIF($B$7:$B$42,G35,$D$7:$D$42) -> 0
B36: DN100 | D36: 27.05 | G36: DN15 | H36: =SUMIF($B$7:$B$42,G36,$D$7:$D$42) -> 0
B37: DN80 | D37: 4.69 | G37: DN12 | H37: =SUMIF($B$7:$B$42,G37,$D$7:$D$42) -> 98.91
B38: DN65 | D38: 26.5
B39: DN65 | D39: 16.5
B40: DN65 | D40: 46.06 | G40: Cooling
...

Sheet Worksheet_Ducts
A1: Ventilation (on roof)
A2: Type | B2: Element | C2: Width | D2: Length | E2: Height | F2: Thickness | G2: Volume | I2: Type | J2: Element | K2: Width | L2: Length | M2: Height | N2: Thickness | O2: Volume | Q2: Type | R2: Element | S2: Width | T2: Length | U2: Height | V2: Thickness | W2: Volume | Y2: Type | Z2: Element | AA2: Width | AB2: Length | AC2: Height | AD2: Thickness | AE2: Volume | AG2: Type | AH2: Element | AI2: Width | AJ2: Length | AK2: Height | AL2: Thickness | AM2: Volume
A3: Anlage 1b | I3: Anlage 1a | Q3: Anlage 1.1 | Y3: Anlage 2.0 | AG3: Anlage 2.1
B4: Housing frame (below) | C4: 2.45 | D4: 10.79 | E4: 1.26 | F4: 0.035 | G4: =(C4*E4*2+C4*D4*2+E4*D4*2)*F4 -> 3.018253 | J4: Housing frame (below) | K4: 1.61 | L4: 9.79 | M4: 1.26 | N4: 0.035 | O4: =(K4*M4*2+K4*L4*2+M4*L4*2)*N4 -> 2.108813 | R4: Housing frame (below) | S4: 0.98 | T4: 8.1 | U4: 0.68 | V4: 0.035 | W4: =(S4*U4*2+S4*T4*2+U4*T4*2)*V4 -> 0.987868 | Z4: Housing frame (below) | AA4: 2.45 | AB4: 10.79 | AC4: 1.26 | AD4: 0.035 | AE4: =(AA4*AC4*2+AA4*AB4*2+AC4*AB4*2)*AD4 -> 3.018253 | AH4: Housing frame (below) | AI4: 0.67 | AJ4: 8.1 | AK4: 0.68 | AL4: 0.035 | AM4: =(AI4*AK4*2+AI4*AJ4*2+AK4*AJ4*2)*AL4 -> 0.797342
B5: Housing frame (upper) | C5: 2.45 | D5: 7.29 | E5: 1.26 | F5: 0.035 | G5: =(C5*E5*2+C5*D5*2+E5*D5*2)*F5 -> 2.109303 | J5: Housing frame (upper) | K5: 1.61 | L5: 7.04 | M5: 1.26 | N5: 0.035 | O5: =(K5*M5*2+K5*L5*2+M5*L5*2)*N5 -> 1.556338 | R5: Housing frame (upper) | S5: 0.98 | T5: 6.66 | U5: 0.68 | V5: 0.035 | W5: =(S5*U5*2+S5*T5*2+U5*T5*2)*V5 -> 0.82054 | Z5: Housing frame (upper) | AA5: 2.45 | AB5: 7.29 | AC5: 1.26 | AD5: 0.035 | AE5: =(AA5*AC5*2+AA5*AB5*2+AC5*AB5*2)*AD5 -> 2.109303 | AH5: Housing frame (upper) | AI5: 0.67 | AJ5: 6.66 | AK5: 0.68 | AL5: 0.035 | AM5: =(AI5*AK5*2+AI5*AJ5*2+AK5*AJ5*2)*AL5 -> 0.661262
B6: Housing Floor | C6: 2.45 | D6: 10.79 | F6: 0.13 | G6: =C6*D6*F6 -> 3.436615 | J6: Housing Floor | K6: 1.61 | L6: 9.79 | N6: 0.13 | O6: =K6*L6*N6 -> 2.049047 | R6: Housing Floor | S6: 0.98 | T6: 8.1 | V6: 0.13 | W6: =S6*T6*V6 -> 1.03194 | Z6: Housing Floor | AA6: 2.45 | AB6: 10.79 | AD6: 0.13 | AE6: =AA6*AB6*AD6 -> 3.436615 | AH6: Housing Floor | AI6: 0.67 | AJ6: 8.1 | AL6: 0.13 | AM6: =AI6*AJ6*AL6 -> 0.70551
B7: Housing Floor | C7: 2.45 | D7: 5.41 | F7: 0.13 | G7: =C7*D7*F7 -> 1.723085 | J7: Housing Floor | K7: 1.61 | L7: 5.7 | N7: 0.13 | O7: =K7*L7*N7 -> 1.19301 | R7: Housing Floor | S7: 0.98 | T7: 5.39 | V7: 0.13 | W7: =S7*T7*V7 -> 0.686686 | Z7: Housing Floor | AA7: 2.45 | AB7: 5.41 | AD7: 0.13 | AE7: =AA7*AB7*AD7 -> 1.723085 | AH7: Housing Floor | AI7: 0.67 | AJ7: 5.39 | AL7: 0.13 | AM7: =AI7*AJ7*AL7 -> 0.469469
B8: Rotary Heat exchanger | C8: 2.37 | D8: 0.33 | E8: 2.64 | J8: Rotary Heat exchanger | K8: 2.37 | L8: 0.33 | M8: 2.64 | R8: Counterflow Heat exchanger | S8: 0.9 | T8: 1.15 | U8: 1.39 | Z8: Rotary Heat exchanger | AA8: 2.37 | AB8: 0.33 | AC8: 2.64 | AH8: Counterflow Heat exchanger | AI8: 0.9 | AJ8: 1.15 | AK8: 1.39
A9: Inlet | B9: Flaps | C9: 2.37 | D9: 0.18 | E9: 1.17 | I9: Inlet | J9: Flaps | K9: 1.57 | L9: 0.18 | M9: 0.16 | Q9: Inlet | R9: Flaps | S9: 0.92 | T9: 0.12 | U9: 0.6 | Y9: Inlet | Z9: Flaps | AA9: 2.37 | AB9: 0.18 | AC9: 1.17 | AG9: Inlet | AH9: Flaps | AI9: 0.6 | AJ9: 0.12 | AK9: 0.6
B10: Filter M5 | C10: 2.37 | D10: 0.1 | E10: 1.17 | J10: Filter M5 | K10: 1.57 | L10: 0.1 | M10: 1.17 | R10: Filter M5 | S10: 0.92 | T10: 0.1 | U10: 0.6 | Z10: Filter M5 | AA10: 2.37 | AB10: 0.6 | AC10: 1.17 | AH10: Filter M5 | AI10: 0.6 | AJ10: 0.1 | AK10: 0.6
B11: Silencer | C11: 2.37 | D11: 0.92 | E11: 1.17 | J11: Silencer | K11: 1.57 | L11: 0.92 | M11: 1.17 | R11: Silencer | S11: 0.92 | T11: 0.92 | U11: 0.6 | Z11: Silencer | AA11: 2.37 | AB11: 0.92 | AC11: 1.17 | AH11: Silencer | AI11: 0.6 | AJ11: 0.62 | AK11: 0.6
B12: Heater | C12: 2.37 | D12: 0.13 | E12: 1.17 | J12: Heater | K12: 1.57 | L12: 0.13 | M12: 1.17 | R12: Filter M5 | S12: 0.92 | T12: 0.1 | U12: 0.6 | Z12: Heater | AA12: 2.37 | AB12: 0.13 | AC12: 1.17 | AH12: Filter M5 | AI12: 0.6 | AJ12: 0.1 | AK12: 0.6
B13: Cooler | C13: 2.37 | D13: 0.18 | E13: 1.17 | J13: Cooler | K13: 1.57 | L13: 0.18 | M13: 1.17 | R13: Silencer | S13: 0.92 | T13: 0.92 | U13: 0.6 | Z13: Cooler | AA13: 2.37 | AB13: 0.18 | AC13: 1.17 | AH13: Silencer | AI13: 0.6 | AJ13: 0.92 | AK13: 0.6
B14: Ventilator F U | C14: 1 | D14: 0.95 | E14: 1.02 | J14: Ventilator F U | K14: 0.82 | L14: 0.74 | M14: 0.6 | Q14: Outlet | R14: Flaps | S14: 0.92 | T14: 0.12 | U14: 0.6 | Z14: Ventilator F U | AA14: 1 | AB14: 0.95 | AC14: 1.02 | AG14: Outlet | AH14: Flaps | AI14: 0.6 | AJ14: 0.12 | AK14: 0.6
B15: Filter F7 | C15: 2.37 | D15: 0.1 | E15: 1.17 | J15: Filter F7 | K15: 1.57 | L15: 0.1 | M15: 1.17 | R15: Silencer | S15: 0.92 | T15: 1.53 | U15: 0.6 | Z15: Filter F7 | AA15: 2.37 | AB15: 0.1 | AC15: 1.17 | AH15: Silencer | AI15: 0.6 | AJ15: 1.53 | AK15: 0.6
B16: Silencer | C16: 2.37 | D16: 1.53 | E16: 1.17 | J16: Silencer | K16: 1.57 | L16: 1.53 | M16: 1.17 | R16: Ventilator F U | S16: 0.92 | T16: 0.37 | U16: 0.38 | Z16: Silencer | AA16: 2.37 | AB16: 1.53 | AC16: 1.17 | AH16: Ventilator F U | AI16: 0.35 | AJ16: 0.37 | AK16: 0.38
A17: Outlet | B17: Flaps | C17: 2.37 | D17: 0.18 | E17: 1.17 | I17: Outlet | J17: Flaps | K17: 1.57 | L17: 0.18 | M17: 1.17 | R17: Heater | S17: 0.92 | T17: 0.15 | U17: 0.6 | Y17: Outlet | Z17: Flaps | AA17: 2.37 | AB17: 0.18 | AC17: 1.17 | AH17: Heater | AI17: 0.6 | AJ17: 0.15 | AK17: 0.6
B18: Silencer | C18: 2.37 | D18: 0.92 | E18: 1.17 | J18: Silencer | K18: 1.57 | L18: 1.22 | M18: 1.17 | R18: Ventilator F U | S18: 0.92 | U18: 0.38 | Z18: Silencer | AA18: 2.37 | AB18: 1.22 | AC18: 1.17 | AH18: Ventilator F U | AI18: 0.35 | AJ18: 0.37 | AK18: 0.38
B19: Ventilator F U | C19: 1 | D19: 0.95 | E19: 1.02 | J19: Ventilator F U | K19: 0.82 | L19: 0.74 | M19: 0.6 | R19: Filter F7 | S19: 0.92 | U19: 0.6 | Z19: Ventilator F U | AA19: 1 | AB19: 0.95 | AC19: 1.02 | AH19: Filter F7 | AI19: 0.6 | AJ19: 0.1 | AK19: 0.6
B20: Silencer | C20: 2.37 | D20: 1.22 | E20: 1.17 | J20: Silencer | K20: 1.57 | L20: 1.22 | M20: 1.17 | R20: Silencer | S20: 0.92 | T20: 1.22 | U20: 0.6 | Z20: Silencer | AA20: 2.37 | AB20: 1.22 | AC20: 1.17 | AH20: Silencer | AI20: 0.6 | AJ20: 0.92 | AK20: 0.6
B21: Filter M5 | C21: 2.37 | D21: 0.6 | E21: 1.17 | J21: Filter M5 | K21: 1.57 | L21: 0.1 | M21: 1.17 | Z21: Filter M5 | AA21: 2.37 | AB21: 0.6 | AC21: 1.17
A24: Roof Ducts
A25: Shaft | B25: Type | C25: Width | D25: Length | E25: Depth | G25: Total Ducts Horizontal 3. OG
A26: Anlage 1 | C26: 1.66 | D26: 3 | E26: 1.33 | G26: Width | H26: Depth | I26: Length
A27: Supply | G27: 1.66 | H27: 1.33 | I27: =SUMPRODUCT(SUMIFS($D$26:$D$43,$C$26:$C$43,G27,$E$26:$E$43,H27)) -> 3
C28: 0.7 | D28: 28.64 | E28: 1.56 | G28: 1.8 | H28: 1.2 | I28: =SUMPRODUCT(SUMIFS($D$26:$D$43,$C$26:$C$43,G28,$E$26:$E$43,H28)) -> 13.4
C29: 0.5 | D29: 47.47 | E29: 0.2 | G29: 1 | H29: 0.5 | I29: =SUMPRODUCT(SUMIFS($D$26:$D$43,$C$26:$C$43,G29,$E$26:$E$43,H29)) -> 57.1
C30: 1 | D30: 6.4 | E30: 0.5 | G30: 0.7 | H30: 1.56 | I30: =SUMPRODUCT(SUMIFS($D$26:$D$43,$C$26:$C$43,G30,$E$26:$E$43,H30)) -> 54.88
G31: 0.5 | H31: 0.5 | I31: =SUMPRODUCT(SUMIFS($D$26:$D$43,$C$26:$C$43,G31,$E$26:$E$43,H31)) -> 39.86
A32: Extract | D32: 6 | E32: 0.76 | G32: 0.5 | H32: 0.2 | I32: =SUMPRODUCT(SUMIFS($D$26:$D$43,$C$26:$C$43,G32,$E$26:$E$43,H32)) -> 165.64
C33: 0.7 | D33: 26.24 | E33: 1.56
C34: 0.5 | D34: 45.02 | E34: 0.2
C35: 1 | D35: 8 | E35: 0.5
A36: Anlage 2
A37: Supply | C37: 1.8 | D37: 11.7 | E37: 1.2
C38: 1 | D38: 42.42 | E38: 0.5
C39: 0.5 | D39: 35.45 | E39: 0.2
A40: Extract | C40: 1.8 | D40: 1.7 | E40: 1.2
C41: 1 | D41: 0.28 | E41: 0.5
C42: 0.5 | D42: 39.86 | E42: 0.5
...

Sheet operational Energy
A1: Heating 21/Cooling 26 | V1: fossil energy | W1: green energy mix
A2: Date/Time | B2: System Fans | C2: System Pumps | D2: Heating (Electricity) | E2: Heating (Other fuels) | F2: Cooling (Electricity) | I2: Date/Time | J2: Relative Humidity | K2: Fanger PMV | L2: Fanger PPD | M2: Air Temperature | N2: Radiant Temperature | O2: Operative Temperature | P2: Discomfort hrs (all clothing) | Q2: Outside Dry-Bulb Temperature | U2: kWh | V2: kgCO2eq | W2: kgCO2eq
B3: kWh | C3: kWh | D3: kWh | E3: kWh | F3: kWh | J3: % | L3: % | M3: °C | N3: °C | O3: °C | P3: hrs | Q3: °C | T3: Heating (Other fuels) | U3: =SUM(C16:E16) -> 687360.95 | V3: =U3*'GWP2013'!C12 -> 6667.4012 | W3: =U3*'GWP2013'!C12 -> 6667.4012
A4: 37257 | B4: 75063.99 | C4: 74.5147 | D4: 0 | E4: 117338.3 | F4: 15903.52 | I4: 37257 | J4: 31.59802 | K4: -1.990112 | L4: 71.82177 | M4: 15.44572 | N4: 15.5595 | O4: 15.50261 | P4: 266.8405 | Q4: 1.854738 | T4: Cooling (Electricity) | U4: =F16 -> 565204.04 | V4: =U4*'GWP2013'!C11 -> 54380.354 | W4: =U4*'GWP2013'!C10 -> 5975.8157
A5: 37288 | B5: 67799.73 | C5: 60.63109 | D5: 0 | E5: 98294.83 | F5: 15668.62 | I5: 37288 | J5: 30.31162 | K5: -1.856991 | L5: 66.46806 | M5: 15.78233 | N5: 16.42197 | O5: 16.10215 | P5: 223.4828 | Q5: 2.277493 | T5: Ventilation (Electricity) | U5: =B16 -> 883817.98 | V5: =U5*'GWP2013'!C11 -> 85035.37 | W5: =U5*'GWP2013'!C10 -> 9344.4721
A6: 37316 | B6: 75063.99 | C6: 54.17988 | D6: 0 | E6: 93196.01 | F6: 17868.68 | I6: 37316 | J6: 33.0514 | K6: -1.57131 | L6: 54.9984 | M6: 16.56258 | N6: 17.95522 | O6: 17.2589 | P6: 211.3431 | Q6: 5.527621
A7: 37347 | B7: 72642.58 | C7: 0 | D7: 0 | E7: 65174.11 | F7: 18246.95 | I7: 37347 | J7: 39.94048 | K7: -2.806958 | L7: 69.89732 | M7: 16.86054 | N7: 19.30097 | O7: 18.08075 | P7: 179.6748 | Q7: 10.84507
A8: 37377 | B8: 75063.99 | C8: 0 | D8: 0 | E8: 0 | F8: 84448.7 | I8: 37377 | J8: 46.19346 | K8: -2.552902 | L8: 86.04676 | M8: 17.55857 | N8: 20.21036 | O8: 18.88446 | P8: 162.2419 | Q8: 14.95373
A9: 37408 | B9: 72642.58 | C9: 0 | D9: 0 | E9: 0 | F9: 99270.48 | I9: 37408 | J9: 50.65503 | K9: -2.268795 | L9: 79.65667 | M9: 18.15439 | N9: 21.1615 | O9: 19.65795 | P9: 74.09298 | Q9: 18.09049
A10: 37438 | B10: 75063.99 | C10: 0 | D10: 0 | E10: 0 | F10: 117580.8 | I10: 37438 | J10: 48.71449 | K10: -1.912666 | L10: 69.19836 | M10: 18.98549 | N10: 22.47653 | O10: 20.73101 | P10: 47.45926 | Q10: 19.74476
A11: 37469 | B11: 75063.99 | C11: 0.005173 | D11: 0 | E11: 0 | F11: 112773.2 | I11: 37469 | J11: 50.55723 | K11: -2.052617 | L11: 73.50538 | M11: 18.63737 | N11: 21.94474 | O11: 20.29106 | P11: 65.24557 | Q11: 18.84516 | T11: Date/Time | U11: Room Electricity | V11: Lighting | W11: System Fans | X11: System Pumps | Y11: Heating (Other fuels) | Z11: Cooling (Electricity)
A12: 37500 | B12: 72642.58 | C12: 0.118581 | D12: 0 | E12: 170.4404 | F12: 44191.07 | I12: 37500 | J12: 49.99456 | K12: -2.536148 | L12: 86.09879 | M12: 17.53609 | N12: 20.2152 | O12: 18.87564 | P12: 140.3928 | Q12: 15.11809 | U12: kWh | V12: kWh | W12: kWh | X12: kWh | Y12: kWh | Z12: kWh
A13: 37530 | B13: 75063.99 | C13: 46.87611 | D13: 0 | E13: 88166.88 | F13: 17936.26 | I13: 37530 | J13: 43.80106 | K13: -1.339526 | L13: 44.8437 | M13: 17.23149 | N13: 18.74216 | O13: 17.98683 | P13: 204.8723 | Q13: 10.20507 | T13: 0 | U13: 452205,9 | V13: 653535,6 | W13: 1322626 | X13: 526,6388 | Y13: 921709 | Z13: 1135550
A14: 37561 | B14: 72642.58 | C14: 64.63991 | D14: 0 | E14: 106214.7 | F14: 11176.12 | I14: 37561 | J14: 36.98989 | K14: -1.782141 | L14: 64.09747 | M14: 16.01584 | N14: 16.54208 | O14: 16.27896 | P14: 222.3242 | Q14: 5.023194
A15: 37591 | B15: 75063.99 | C15: 74.91982 | D15: 214.4054 | E15: 117625.1 | F15: 10139.64 | I15: 37591 | J15: 32.00509 | K15: -2.024098 | L15: 72.76512 | M15: 15.3454 | N15: 15.34857 | O15: 15.34698 | P15: 249.5117 | Q15: 2.065928 | Y15: =Y13/10135 -> 90.943167 | Z15: =Z13/10135 -> 112.04243
A16: Total | B16: =SUM(B4:B15) -> 883817.98 | C16: =SUM(C4:C15) -> 375.88526 | D16: =SUM(D4:D15) -> 214.4054 | E16: =SUM(C4:E15) -> 686770.66 | F16: =SUM(F4:F15) -> 565204.04 | I16: 37257 | J16: 41.20457 | K16: =AVERAGE(K4:K15) -> -2.0578553 | L16: =AVERAGE(L4:L15) -> 69.949817 | M16: =AVERAGE(M4:M15) -> 17.009651 | N16: =AVERAGE(N4:N15) -> 18.823233 | O16: =AVERAGE(O4:O15) -> 17.916442 | P16: =SUM(P4:P15) -> 2047.4819 | Q16: 10.42516

Sheet GWP2013
A1: Material | B1: Unit | C1: kgCO2eq | D1: kg/m | E1: kgCO2eq - kg
A2: PE foam | B2: kg | C2: 3.903
A3: Rockwool | B3: kg | C3: 1.084
A4: C-Steel | B4: kg | C4: 5.111
A5: Polyethylene pipi | B5: m | C5: 9.4317 | D5: 3 | E5: =C5/D5 -> 3.1439
A6: Steel | B6: kg | C6: 2.1588
A7: galvanized sheet steel | B7: kg | C7: 5.111
A8: Copper/Aluminium Combination | B8: kg | C8: 8.2452
A9: R-1234ze | B9: kg | C9: 17.606
A10: electricity, medium voltage, label-certified | B10: kWh | C10: 0.010572847
A11: electricity, medium voltage | B11: kWh | C11: 0.096213668
A12: District Heating | B12: kWh | C12: 0.0097
A13: High Performance Convector | B13: Copper/Aluminium Combination
A14: Aluminium | B14: kg | C14: 19.542
A15: Nitrile Butadiene Rubber / Kautschuck | B15: kg | C15: 2.793
A16: Polyamid | B16: kg | C16: 8.5311
A17: Air Chiller | B17: 1000kg | C17: 328.9
A18: Steel Panel | B18: kg | C18: =C6 -> 2.1588
